from django.core.exceptions import ValidationError

def validate_custom_user_funcionario(instance):
    pass